<mujoco model="aliengo_description">
	<compiler angle="radian" meshdir="../meshes" />
	<!-- <size njmax="4000" nconmax="2000" /> -->
	<size njmax="500" nconmax="100" nuser_actuator="1" />
	<option timestep="0.001" iterations="50" tolerance="1e-10" solver="Newton" jacobian="dense" cone="pyramidal" />
	<default>
		<joint limited="false" damping="0.2" pos="0 0 0" armature="0.03" />
		<motor ctrllimited="false" forcelimited="false" />
		<default class="collision">
			<geom condim="3" group="0" rgba="1 0.423529 0.0392157 1" />
		</default>
		<default class="visual">
			<geom condim="3" material="matgeom" type="mesh" group="1" conaffinity="0" contype="0" />
		</default>
	</default>
	<visual>
		<map force="0.01" zfar="30" />
		<rgba haze="0.15 0.25 0.35 1" />
		<quality shadowsize="2048" />
		<global offwidth="800" offheight="800" />
	</visual>
	<asset>
		<mesh name="trunk_mesh" file="trunk.stl" />
		<mesh name="FR_hip_mesh" file="hip.stl" />
		<mesh name="FR_thigh_mesh" file="thigh_mirror.stl" />
		<mesh name="FR_calf_mesh" file="calf.stl" />
		<mesh name="FL_hip_mesh" file="hip.stl" />
		<mesh name="FL_thigh_mesh" file="thigh.stl" />
		<mesh name="FL_calf_mesh" file="calf.stl" />
		<mesh name="RR_hip_mesh" file="hip.stl" />
		<mesh name="RR_thigh_mesh" file="thigh_mirror.stl" />
		<mesh name="RR_calf_mesh" file="calf.stl" />
		<mesh name="RL_hip_mesh" file="hip.stl" />
		<mesh name="RL_thigh_mesh" file="thigh.stl" />
		<mesh name="RL_calf_mesh" file="calf.stl" />
		<texture type="skybox" builtin="gradient" rgb1="0.3 0.5 0.7" rgb2="0 0 0" width="512" height="512" />
		<texture name="texplane" type="2d" builtin="checker" rgb1=".2 .3 .4" rgb2=".1 0.15 0.2" width="512" height="512" mark="cross" markrgb=".8 .8 .8" />
		<texture name="texgeom" type="cube" builtin="flat" mark="cross" width="127" height="1278" rgb1="0.8 0.6 0.4" rgb2="0.8 0.6 0.4" markrgb="1 1 1" random="0.01" />
		<material name="matplane" reflectance="0.3" texture="texplane" texrepeat="1 1" texuniform="true" />
		<material name="matgeom" texture="texgeom" texuniform="true" rgba="0.8 0.6 .4 1" />
	</asset>
	<worldbody>
		<light directional="false" diffuse=".2 .2 .2" specular="0 0 0" pos="0 0 5" dir="0 0 -1" castshadow="false" />
		<light mode="targetbodycom" target="trunk" directional="false" diffuse=".8 .8 .8" specular="0.3 0.3 0.3" pos="0 0 4.0" dir="0 0 -1" />
		<geom type="plane" size="1 1 0.1" rgba=".9 0 0 1" />
		<!-- trunk -->
		<body name="trunk" pos="0 0 1.4">
			<inertial pos="0.008465 0.004045 -0.000763" quat="1 0 0 0" mass="9.041" fullinertia="0.033260231 0.16117211 0.17460442 0.000451628 0.000487603 4.8356e-05" />
			<freejoint name="root" />
			<geom class="collision" size="0.3235 0.075 0.056" type="box" />
			<geom class="visual" mesh="trunk_mesh" />
			<!-- site for root imu sensor -->
			<site name="imu" size="0.0005 0.0005 0.0005" pos="0 0 0" />
			<!-- front right -->
			<body name="FR_hip" pos="0.2399 -0.051 0">
				<inertial pos="-0.022191 -0.015144 -1.5e-05" quat="0.0135493 0.706835 -0.0117635 0.707151" mass="1.993" fullinertia="0.002903894 0.004907517 0.005586944 7.185e-05 -1.262e-06 1.75e-06" />
				<joint name="FR_hip_joint" axis="1 0 0" limited="true" range="-1.22173 1.22173" />
				<geom class="collision" size="0.046 0.0209" pos="0 -0.083 0" quat="0.707107 0.707107 0 0" type="cylinder" />
				<geom class="visual" mesh="FR_hip_mesh" />
				<body name="FR_thigh" pos="0 -0.083 0">
				<!-- quant changed here -->
					<inertial pos="-0.005607 0.003877 -0.048199" quat="1 0 0 0" mass="0.639" fullinertia="0.005666803 0.005847229 0.000369811 -3.597e-06 0.000491446 -1.0086e-05" />
					<joint name="FR_thigh_joint" axis="0 1 0" />
					<geom class="collision" size="0.125 0.0187 0.0215" pos="0 0 -0.125" quat="0.707107 0 0.707107 0" type="box" />
					<geom class="visual" mesh="FR_thigh_mesh" />
					<body name="FR_calf" pos="0 0 -0.25">
					<!-- pos changed here, quant seems sus -->
						<inertial pos="0.002781 6.3e-05 -0.142518" quat="1 0 0 0" mass="0.207" fullinertia="0.006341369 0.006355157 3.9188e-05 -3e-09 -8.7951e-05 -1.336e-06" />
						<joint name="FR_calf_joint" axis="0 1 0" limited="true" range="-2.77507 -0.645772" />
						<geom class="collision" size="0.125 0.0104 0.008" pos="0 0 -0.125" quat="0.707107 0 0.707107 0" type="box" />
						<geom class="visual" mesh="FR_calf_mesh" />
						<body name="FR_foot" pos="0 0 -0.25">
							<inertial pos="0 0 0" mass="0.06" fullinertia="1.6854e-05 1.6854e-05 1.6854e-05 0 0 0" />
							<geom class="collision" size="0.0265" pos="0 0 0" rgba="0 0.8 0 1" type="sphere" />
						</body>
					</body>
				</body>
			</body>
			<!-- front left -->
			<body name="FL_hip" pos="0.2399 0.051 0">
			<!-- quant changed here -->
				<inertial pos="-0.022191 0.015144 -1.5e-05" quat="1 0 0 0" mass="1.993" fullinertia="0.002903894 0.004907517 0.005586944 -7.185e-05 -1.262e-06 -1.75e-06" />
				<joint name="FL_hip_joint" axis="1 0 0" limited="true" range="-1.22173 1.22173" />
				<geom class="collision" size="0.046 0.0209" pos="0 0.083 0" quat="0.707107 0.707107 0 0" type="cylinder" />
				<geom class="visual" mesh="FL_hip_mesh" />
				<body name="FL_thigh" pos="0 0.083 0">
				<!-- Changed quant here -->
					<inertial pos="-0.005607 -0.003877 -0.048199" quat="1 0 0 0" mass="0.639" fullinertia="0.005666803 0.005847229 0.000369811 3.597e-06 0.000491446 1.0086e-05" />
					<joint name="FL_thigh_joint" axis="0 1 0" />
					<geom class="collision" size="0.125 0.0187 0.0215" pos="0 0 -0.125" quat="0.707107 0 0.707107 0" type="box" />
					<geom class="visual" mesh="FL_thigh_mesh" />
					<body name="FL_calf" pos="0 0 -0.25">
					<!-- Position changed, quant seems sus -->
						<inertial pos="0.002781 6.3e-05 -0.142518" quat="0.707462 0.00517582 0.00535172 0.706712" mass="0.207" fullinertia="0.006341369 0.006355157 3.9188e-05 -3e-09 -8.7951e-05 -1.336e-06" />
						<joint name="FL_calf_joint" axis="0 1 0" limited="true" range="-2.77507 -0.645772" />
						<geom class="collision" size="0.125 0.0104 0.008" pos="0 0 -0.125" quat="0.707107 0 0.707107 0" type="box" />
						<geom class="visual" mesh="FL_calf_mesh" />
						<body name="FL_foot" pos="0 0 -0.25">
							<inertial pos="0 0 0" mass="0.06" fullinertia="1.6854e-05 1.6854e-05 1.6854e-05 0 0 0" />
							<geom class="collision" size="0.0265" pos="0 0 0" rgba="0 0.8 0 1" type="sphere" />
						</body>
					</body>
				</body>
			</body>
			<!-- rear right -->
			<body name="RR_hip" pos="-0.2399 -0.051 0">
				<inertial pos="0.022191 -0.015144 -1.5e-05" quat="-0.0117635 0.707151 0.0135493 0.706835" mass="1.993" fullinertia="0.002903894 0.004907517 0.005586944 -7.185e-05 1.262e-06 1.75e-06" />
				<joint name="RR_hip_joint" axis="1 0 0" limited="true" range="-1.22173 1.22173" />
				<geom class="collision" size="0.046 0.0209" pos="0 -0.083 0" quat="0.707107 0.707107 0 0" type="cylinder" />
				<geom class="visual" mesh="RR_hip_mesh" />
				<body name="RR_thigh" pos="0 -0.083 0">
					<inertial pos="-0.005607 0.003877 -0.048199" quat="0.694544 -0.0335669 -0.031246 0.717987" mass="0.639" fullinertia="0.005666803 0.005847229 0.000369811 -3.597e-06 0.000491446 -1.0086e-05" />
					<joint name="RR_thigh_joint" axis="0 1 0" />
					<geom class="collision" size="0.125 0.0187 0.0215" pos="0 0 -0.125" quat="0.707107 0 0.707107 0" type="box" />
					<geom class="visual" mesh="RR_thigh_mesh" />
					<body name="RR_calf" pos="0 0 -0.25">
						<inertial pos="0.00215606 4.88427e-05 -0.166671" quat="0.707462 0.00517582 0.00535172 0.706712" mass="0.267" fullinertia="0.006341369 0.006355157 3.9188e-05 -3e-09 -8.7951e-05 -1.336e-06" />
						<joint name="RR_calf_joint" axis="0 1 0" limited="true" range="-2.77507 -0.645772" />
						<geom class="collision" size="0.125 0.0104 0.008" pos="0 0 -0.125" quat="0.707107 0 0.707107 0" type="box" />
						<geom class="visual" mesh="RR_calf_mesh" />
						<body name="RR_foot" pos="0 0 -0.25">
							<inertial pos="0 0 0" mass="0.06" fullinertia="1.6854e-05 1.6854e-05 1.6854e-05 0 0 0" />
							<geom class="collision" size="0.0265" pos="0 0 0" rgba="0 0.8 0 1" type="sphere" />
						</body>
					</body>
				</body>
			</body>
			<!-- rear left -->
			<body name="RL_hip" pos="-0.2399 0.051 0">
				<inertial pos="0.022191 0.015144 -1.5e-05" quat="0.0117635 0.707151 -0.0135493 0.706835" mass="1.993" fullinertia="0.002903894 0.004907517 0.005586944 7.185e-05 1.262e-06 -1.75e-06" />
				<joint name="RL_hip_joint" axis="1 0 0" limited="true" range="-1.22173 1.22173" />
				<geom class="collision" size="0.046 0.0209" pos="0 0.083 0" quat="0.707107 0.707107 0 0" type="cylinder" />
				<geom class="visual" mesh="RL_hip_mesh" />
				<body name="RL_thigh" pos="0 0.083 0">
					<inertial pos="-0.005607 -0.003877 -0.048199" quat="0.717987 -0.031246 -0.0335669 0.694544" mass="0.639" fullinertia="0.005666803 0.005847229 0.000369811 3.597e-06 0.000491446 1.0086e-05" />
					<joint name="RL_thigh_joint" axis="0 1 0" />
					<geom class="collision" size="0.125 0.0187 0.0215" pos="0 0 -0.125" quat="0.707107 0 0.707107 0" type="box" />
					<geom class="visual" mesh="RL_thigh_mesh" />
					<body name="RL_calf" pos="0 0 -0.25">
						<inertial pos="0.00215606 4.88427e-05 -0.166671" quat="0.707462 0.00517582 0.00535172 0.706712" mass="0.267" fullinertia="0.006341369 0.006355157 3.9188e-05 -3e-09 -8.7951e-05 -1.336e-06" />
						<joint name="RL_calf_joint" axis="0 1 0" limited="true" range="-2.77507 -0.645772" />
						<geom class="collision" size="0.125 0.0104 0.008" pos="0 0 -0.125" quat="0.707107 0 0.707107 0" type="box" />
						<geom class="visual" mesh="RL_calf_mesh" />
						<body name="RL_foot" pos="0 0 -0.25">
							<inertial pos="0 0 0" mass="0.06" diaginertia="1.6854e-05 1.6854e-05 1.6854e-05 0 0 0" />
							<geom class="collision" size="0.0265" pos="0 0 0" rgba="0 0.8 0 1" type="sphere" />
						</body>
					</body>
				</body>
			</body>
		</body>
	</worldbody>
	<actuator>
		<!-- FR leg -->
		<motor name="FR_hip_motor" joint="FR_hip_joint" />
		<motor name="FR_thigh_motor" joint="FR_thigh_joint" />
		<motor name="FR_calf_motor" joint="FR_calf_joint" />
		<!-- FL leg -->
		<motor name="FL_hip_motor" joint="FL_hip_joint" />
		<motor name="FL_thigh_motor" joint="FL_thigh_joint" />
		<motor name="FL_calf_motor" joint="FL_calf_joint" />
		<!-- RR leg -->
		<motor name="RR_hip_motor" joint="RR_hip_joint" />
		<motor name="RR_thigh_motor" joint="RR_thigh_joint" />
		<motor name="RR_calf_motor" joint="RR_calf_joint" />
		<!-- RL leg -->
		<motor name="RL_hip_motor" joint="RL_hip_joint" />
		<motor name="RL_thigh_motor" joint="RL_thigh_joint" />
		<motor name="RL_calf_motor" joint="RL_calf_joint" />
	</actuator>
	<sensor>
		<!-- imu -->
		<gyro name="Accelerometer_gyro" site="imu" />
		<accelerometer name="Accelerometer_accelerometer" site="imu" />
	</sensor>
</mujoco>
